2021-06-08 18:18:36,320 dellemc_isilon_gatherfacts.py INFO : Got python SDK instance for provisioning on Isilon 
2021-06-08 18:20:46,256 connectionpool.py WARNING : Retrying (Retry(total=2, connect=None, read=None, redirect=None, status=None)) after connection broken by 'NewConnectionError('<urllib3.connection.VerifiedHTTPSConnection object at 0x7fbfef80ec18>: Failed to establish a new connection: [Errno 110] Connection timed out',)': /session/1/session
2021-06-08 18:22:57,328 connectionpool.py WARNING : Retrying (Retry(total=1, connect=None, read=None, redirect=None, status=None)) after connection broken by 'NewConnectionError('<urllib3.connection.VerifiedHTTPSConnection object at 0x7fbfef80ed30>: Failed to establish a new connection: [Errno 110] Connection timed out',)': /session/1/session
2021-06-08 18:25:08,400 connectionpool.py WARNING : Retrying (Retry(total=0, connect=None, read=None, redirect=None, status=None)) after connection broken by 'NewConnectionError('<urllib3.connection.VerifiedHTTPSConnection object at 0x7fbfef3392b0>: Failed to establish a new connection: [Errno 110] Connection timed out',)': /session/1/session
2021-06-08 18:27:19,472 dellemc_isilon_gatherfacts.py ERROR : Get Attributes List for Isilon cluster: 192.168.3.11 failed with error: HTTPSConnectionPool(host='192.168.3.11', port=8080): Max retries exceeded with url: /session/1/session (Caused by NewConnectionError('<urllib3.connection.VerifiedHTTPSConnection object at 0x7fbfef343470>: Failed to establish a new connection: [Errno 110] Connection timed out',))
2021-06-08 18:31:20,897 dellemc_isilon_gatherfacts.py INFO : Got python SDK instance for provisioning on Isilon 
2021-06-08 18:33:30,160 connectionpool.py WARNING : Retrying (Retry(total=2, connect=None, read=None, redirect=None, status=None)) after connection broken by 'NewConnectionError('<urllib3.connection.VerifiedHTTPSConnection object at 0x7fb006847a90>: Failed to establish a new connection: [Errno 110] Connection timed out',)': /session/1/session
2021-06-08 18:35:41,232 connectionpool.py WARNING : Retrying (Retry(total=1, connect=None, read=None, redirect=None, status=None)) after connection broken by 'NewConnectionError('<urllib3.connection.VerifiedHTTPSConnection object at 0x7fb006847ba8>: Failed to establish a new connection: [Errno 110] Connection timed out',)': /session/1/session
2021-06-08 18:37:52,304 connectionpool.py WARNING : Retrying (Retry(total=0, connect=None, read=None, redirect=None, status=None)) after connection broken by 'NewConnectionError('<urllib3.connection.VerifiedHTTPSConnection object at 0x7fb0063730f0>: Failed to establish a new connection: [Errno 110] Connection timed out',)': /session/1/session
2021-06-08 18:40:03,376 dellemc_isilon_gatherfacts.py ERROR : Get Attributes List for Isilon cluster: 192.168.3.11 failed with error: HTTPSConnectionPool(host='192.168.3.11', port=8080): Max retries exceeded with url: /session/1/session (Caused by NewConnectionError('<urllib3.connection.VerifiedHTTPSConnection object at 0x7fb00637f128>: Failed to establish a new connection: [Errno 110] Connection timed out',))
